<mujocoinclude>
    <body childclass="hexy" name="Hexy_2" pos="0 0 0.06" euler="-1.570796 0 -1.570796">
    <camera mode="fixed" name = "indi_eye_camera_2" pos ="0.12 0.1 0.00" euler="1.570796 0 -1.570796" fovy = "100"/>
        <!-- Torso  -->
        <geom class="belly" name="Torso_2" mesh="Bulk" rgba="1 0.3 0.3 1"/>
        <geom class="collision" type="mesh" mesh="BulkCollision" euler="1.570796 1.570796 0"/>
        <inertial pos="0.038378 0.011283 -2.4509e-05" quat="1 -0.000159067 -3.52117e-06 -8.80146e-05" mass="1.0" diaginertia="0.00058735 0.00035464 0.00024547" />
        <!-- Front Right Leg -->
        <body name="FrontRightThigh_2" pos="0.0133 0.076604 -0.064279" quat="0.67 -0.23 0.67 -0.23" >
            <inertial pos="0.000650729 0.00390237 0.0206345" quat="0.565059 0.407617 0.353554 0.624144" mass="0.05" diaginertia="4.10825e-06 4.04383e-06 3.93464e-06" />
            <joint name="FR1_2" range="-1.5 1.5"  pos="0 0 0" axis="0 0 1"/>
            <geom class="thigh" rgba="1 0.3 0.3 1" />
            <geom class="collision" name="T_FRt1" type="box" pos="0.023 0 0.02" size="0.003 0.012 0.018"/>
            <geom class="collision" name="T_FRt2" type="box" pos="-0.023 0.009 0.02" size="0.003 0.021 0.018"/>
            <body name="FrontRightShin_2" pos="0 0.026 0.02015" quat="0 1 0 1">
                <inertial pos="7.00279e-05 -0.0244376 -0.00118476" quat="0.707108 0.707106 0 0" mass="0.05" diaginertia="6.21248e-06 5.7647e-06 2.30821e-06" />
                <joint name="FR2_2" class="shin" range="-1.5 1.5" pos="0 0 0" axis="0 0 1"/>
                <geom class="shin"/>
                <geom class="collision" name="T_FRs1" type="box" pos="0 -0.0245 0" size="0.012 0.0345 0.014"/>
                <body name="FrontRightFoot_2" pos="0 -0.04887 0" quat="1 -1 1 -1">
                    <inertial pos="0.0170134 0.00029768 1.52199e-09" quat="3.18245e-06 0.707107 -3.68379e-07 0.707106" mass="0.02" diaginertia="1.76103e-06 1.37282e-06 1.01637e-06" />
                    <joint name="FR3_2" class="foot" range="-1.5 1.5" pos="0 0 0" axis="0 1 0"/>
                    <geom class="foot"/>
                    <geom class="collision" name="T_FRf1" type="box" pos="0.013 0.023 0" size="0.018 0.0033 0.005"/>
                    <geom class="collision" name="T_FRf2" type="box" pos="0.013 -0.023 0" size="0.018 0.0033 0.005"/>
                    <geom class="collision" name="T_FRf3" type="box" pos="0 0.023 0" size="0.005 0.0033 0.017"/>
                    <geom class="collision" name="T_FRf4" euler="0 -1.571 0" type="capsule" pos="0.038 0 0" size="0.005 0.01"/>
                    <site name="FRfoot_2" rgba="1 0.3 0.3 1"/>
                </body>
            </body>
        </body>
        <!-- Middle Right Leg -->
        <body name="MiddleRightThigh_2" pos="0.0133 0 -0.1" quat="0.5 -0.5 0.5 -0.5">
            <inertial pos="0.000650726 0.00390238 0.0206345" quat="0.565059 0.407618 0.353555 0.624142" mass="0.05" diaginertia="4.10825e-06 4.04383e-06 3.93464e-06" />
            <joint name="MR1_2" range="-1.5 1.5" pos="0 0 0" axis="0 0 1"/>
            <geom class="thigh" rgba="1 0.3 0.3 1"/>
            <geom class="collision" name="T_MRt1" type="box" pos="0.023 0 0.02" size="0.003 0.012 0.018"/>
            <geom class="collision" name="T_MRt2" type="box" pos="-0.023 0.009 0.02" size="0.003 0.021 0.018"/>
            <body name="MiddleRightShin_2" pos="0 0.026 0.02015" quat="0 1 0 1">
                <inertial pos="6.99965e-05 -0.0244375 -0.00118476" quat="0.707107 0.707107 -8.09775e-06 8.09775e-06" mass="0.05" diaginertia="6.21247e-06 5.7647e-06 2.30821e-06" />
                <joint name="MR2_2" class="shin" range="-1.5 1.5" pos="0 0 0" axis="0 0 1"/>
                <geom class="shin"/>
                <geom class="collision" name="T_MRs1" type="box" pos="0 -0.0245 0" size="0.012 0.0345 0.014"/>
                <body name="MiddleRightFoot_2" pos="0.00014 -0.04887 0" quat="1 -1 1 -1">
                    <inertial pos="0.0170134 0.00029772 -2.57158e-08" quat="4.56968e-06 0.707107 1.45044e-07 0.707107" mass="0.02" diaginertia="1.76103e-06 1.37282e-06 1.01637e-06" />
                    <joint name="MR3_2" class="foot" range="-1.5 1.5" pos="0 0 0" axis="0 1 0"/>
                    <geom class="foot"/>
                    <geom class="collision" name="T_MRf1" type="box" pos="0.013 0.023 0" size="0.018 0.0033 0.005"/>
                    <geom class="collision" name="T_MRf2" type="box" pos="0.013 -0.023 0" size="0.018 0.0033 0.005"/>
                    <geom class="collision" name="T_MRf3" type="box" pos="0 0.023 0" size="0.005 0.0033 0.017"/>
                    <geom class="collision" name="T_MRf4" euler="0 -1.571 0" type="capsule" pos="0.038 0 0" size="0.005 0.01"/>
                    <site name="MRfoot_2" rgba="1 1 0.3 1"/>
                </body>
            </body>
        </body>
        <!-- Back Right Leg -->
        <body name="BackRightThigh_2" pos="0.0133 -0.0766044 -0.0642788" quat="0.23 -0.67 0.23 -0.67">
            <inertial pos="0.000650732 0.00390238 0.0206345" quat="0.56506 0.40762 0.353558 0.62414" mass="0.05" diaginertia="4.10825e-06 4.04383e-06 3.93464e-06" />
            <joint name="BR1_2" range="-1.5 1.5" pos="0 0 0" axis="0 0 1"/>
            <geom class="thigh" rgba="1 0.3 0.3 1"/>
            <geom class="collision" name="T_BRt1" type="box" pos="0.023 0 0.02" size="0.003 0.012 0.018"/>
            <geom class="collision" name="T_BRt2" type="box" pos="-0.023 0.009 0.02" size="0.003 0.021 0.018"/>
            <body name="BackRightShin_2" pos="0 0.026 0.02015" quat="-1 0 -1 0">
                <inertial pos="-6.99677e-05 0.0244324 -0.00118475" quat="0.707108 0.707106 0 0" mass="0.05" diaginertia="6.21248e-06 5.7647e-06 2.30821e-06" />
                <joint name="BR2_2" class="shin" range="-1.5 1.5" pos="0 0 0" axis="0 0 1"/>
                <geom class="shin" euler="0 0 -3.141593"/>
                <geom class="collision" name="T_BRs1" type="box" pos="0 0.0245 0" size="0.012 0.0345 0.014"/>
                <body name="BackRightFoot_2" pos="-0.00014 0.04887 0" quat="1 -1 -1 1">
                    <inertial pos="0.0170134 0.000297742 -3.74929e-08" quat="5.09579e-06 0.707107 3.37696e-07 0.707106" mass="0.02" diaginertia="1.76103e-06 1.37282e-06 1.01637e-06" />
                    <joint name="BR3_2" class="foot" range="-1.5 1.5" pos="0 0 0" axis="0 1 0"/>
                    <geom class="foot"/>
                    <geom class="collision" name="T_BRf1" type="box" pos="0.013 0.023 0" size="0.018 0.0033 0.005"/>
                    <geom class="collision" name="T_BRf2" type="box" pos="0.013 -0.023 0" size="0.018 0.0033 0.005"/>
                    <geom class="collision" name="T_BRf3" type="box" pos="0 0.023 0" size="0.005 0.0033 0.017"/>
                    <geom class="collision" name="T_BRf4" euler="0 -1.571 0" type="capsule" pos="0.038 0 0" size="0.005 0.01"/>
                    <site name="BRfoot_2" rgba="0.3 1 0.3 1"/>
                </body>
            </body>
        </body>
        <!-- Front Left Leg -->
        <body name="FrontLeftThigh_2" pos="0.0133 0.0766044 0.0642788" quat="0.67 0.23 0.67 0.23">
            <inertial pos="0.000650732 0.00390238 0.0206345" quat="0.56506 0.40762 0.353558 0.62414" mass="0.05" diaginertia="4.10825e-06 4.04383e-06 3.93464e-06" />
            <joint name="FL1_2" range="-1.5 1.5" pos="0 0 0" axis="0 0 1"/>
            <geom class="thigh" rgba="1 0.3 0.3 1"/>
            <geom class="collision" name="T_FLt1" type="box" pos="0.023 0 0.02" size="0.003 0.012 0.018"/>
            <geom class="collision" name="T_FLt2" type="box" pos="-0.023 0.009 0.02" size="0.003 0.021 0.018"/>
            <body name="FrontLeftShin_2" pos="0 0.026 0.02015" quat="0 1 0 1">
                <inertial pos="6.99987e-05 -0.0244375 -0.00118475" quat="0.707107 0.707107 -8.15956e-06 8.15956e-06" mass="0.05" diaginertia="6.21248e-06 5.7647e-06 2.30821e-06" />
                <joint name="FL2_2" class="shin" range="-1.5 1.5" pos="0 0 0" axis="0 0 1"/>
                <geom class="shin"/>
                <geom class="collision" name="T_FLs1" type="box" pos="0 -0.0245 0" size="0.012 0.0345 0.014"/>
                <body name="FrontLeftFoot_2" pos="0.00014 -0.04887 0" quat="1 -1 1 -1">
                    <inertial pos="0.017013 0.00029773 -3.1875e-08" quat="4.82555e-06 0.707107 6.15082e-07 0.707106" mass="0.02" diaginertia="1.761e-06 1.3728e-06 1.0164e-06" />
                    <joint name="FL3_2" class="foot" range="-1.5 1.5" pos="0 0 0" axis="0 1 0"/>
                    <geom class="foot"/>
                    <geom class="collision" name="T_FLf1" type="box" pos="0.013 0.023 0" size="0.018 0.0033 0.005"/>
                    <geom class="collision" name="T_FLf2" type="box" pos="0.013 -0.023 0" size="0.018 0.0033 0.005"/>
                    <geom class="collision" name="T_FLf3" type="box" pos="0 0.023 0" size="0.005 0.0033 0.017"/>
                    <geom class="collision" name="T_FLf4" euler="0 -1.571 0" type="capsule" pos="0.038 0 0" size="0.005 0.01"/>
                    <site name="FLfoot_2" rgba="0.3 1 1 1"/>
                </body>
            </body>
        </body>
        <!-- Middle Left Leg -->
        <body name="MiddleLeftThigh_2" pos="0.0133 0 0.1" quat="0.5 0.5 0.5 0.5">
            <inertial pos="0.00065072 0.0039024 0.020635" quat="0.565132 0.407532 0.35351 0.624158" mass="0.05" diaginertia="4.10826e-06 4.04379e-06 3.93464e-06" />
            <joint name="ML1_2" range="-1.5 1.5" pos="0 0 0" axis="0 0 1"/>
            <geom class="thigh" rgba="1 0.3 0.3 1"/>
            <geom class="collision" name="T_MLt1" type="box" pos="0.023 0 0.02" size="0.003 0.012 0.018"/>
            <geom class="collision" name="T_MLt2" type="box" pos="-0.023 0.009 0.02" size="0.003 0.021 0.018"/>
            <body name="MiddleLeftShin_2" pos="0 0.026 0.02015" quat="0 1 0 1">
                <inertial pos="7.0023e-05 -0.024438 -0.0011848" quat="0.707107 0.707107 0 0" mass="0.05" diaginertia="6.2125e-06 5.7647e-06 2.3082e-06" />
                <joint name="ML2_2" class="shin" range="-1.5 1.5" pos="0 0 0" axis="0 0 1"/>
                <geom class="shin"/>
                <geom class="collision" name="T_MLs1" type="box" pos="0 -0.0245 0" size="0.012 0.0345 0.014"/>
                <body name="MiddleLeftFoot_2" pos="0.00014 -0.04887 0" quat="1 -1 1 -1">
                    <inertial pos="0.017013 0.00029772 -1.3239e-08" quat="3.94529e-06 0.707107 -1.79691e-07 0.707107" mass="0.02" diaginertia="1.761e-06 1.3728e-06 1.0164e-06" />
                    <joint name="ML3_2" class="foot" range="-1.5 1.5" pos="0 0 0" axis="0 1 0"/>
                    <geom class="foot"/>
                    <geom class="collision" name="T_MLf1" type="box" pos="0.013 0.023 0" size="0.018 0.0033 0.005"/>
                    <geom class="collision" name="T_MLf2" type="box" pos="0.013 -0.023 0" size="0.018 0.0033 0.005"/>
                    <geom class="collision" name="T_MLf3" type="box" pos="0 0.023 0" size="0.005 0.0033 0.017"/>
                    <geom class="collision" name="T_MLf4" euler="0 -1.571 0" type="capsule" pos="0.038 0 0" size="0.005 0.01"/>
                    <site name="MLfoot_2" rgba="0.3 0.3 1 1"/>
                </body>
            </body>
        </body>
        <!-- Back Left Leg -->
        <body name="BackLeftThigh_2" pos="0.0133 -0.0766044 0.0642788" quat="0.23 0.67 0.23 0.67">
            <inertial pos="0.000650729 0.00390237 0.0206345" quat="0.565059 0.407617 0.353554 0.624144" mass="0.05" diaginertia="4.10825e-06 4.04383e-06 3.93464e-06" />
            <joint name="BL1_2" range="-1.5 1.5" pos="0 0 0" axis="0 0 1"/>
            <geom class="thigh" rgba="1 0.3 0.3 1"/>
            <geom class="collision" name="T_BLt1" type="box" pos="0.023 0 0.02" size="0.003 0.012 0.018"/>
            <geom class="collision" name="T_BLt2" type="box" pos="-0.023 0.009 0.02" size="0.003 0.021 0.018"/>
            <body name="BackLeftShin_2" pos="0 0.026 0.02015" quat="0 1 0 1">
                <inertial pos="7.00277e-05 -0.0244376 -0.00118476" quat="0.707108 0.707106 0 0" mass="0.05" diaginertia="6.21248e-06 5.7647e-06 2.30821e-06" />
                <joint name="BL2_2" class="shin" range="-1.5 1.5" pos="0 0 0" axis="0 0 1"/>
                <geom class="shin"/>
                <geom class="collision" name="T_BLs1" type="box" pos="0 -0.0245 0" size="0.012 0.0345 0.014"/>
                <body name="BackLeftFoot_2" pos="0.00014 -0.04887 0" quat="1 -1 1 -1">
                    <inertial pos="0.0170134 0.000297681 9.41423e-10" quat="3.20918e-06 0.707107 -3.75724e-07 0.707106" mass="0.02" diaginertia="1.76103e-06 1.37282e-06 1.01637e-06" />
                    <joint name="BL3_2" class="foot" range="-1.5 1.5" pos="0 0 0" axis="0 1 0"/>
                    <geom class="foot"/>
                    <geom class="collision" name="T_BLf1" type="box" pos="0.013 0.023 0" size="0.018 0.0033 0.005"/>
                    <geom class="collision" name="T_BLf2" type="box" pos="0.013 -0.023 0" size="0.018 0.0033 0.005"/>
                    <geom class="collision" name="T_BLf3" type="box" pos="0 0.023 0" size="0.005 0.0033 0.017"/>
                    <geom class="collision" name="T_BLf4" euler="0 -1.571 0" type="capsule" pos="0.038 0 0" size="0.005 0.01"/>
                    <site name="BLfoot_2" rgba="1 0.3 1 1"/>
                </body>
            </body>
        </body>
    </body>
</mujocoinclude>
